package tj.integration.jei.multi.steam;

import gregicadditions.machines.GATileEntities;
import gregtech.common.blocks.BlockBoilerCasing;
import gregtech.common.blocks.BlockFireboxCasing;
import gregtech.common.blocks.BlockMetalCasing;
import gregtech.common.blocks.MetaBlocks;
import gregtech.common.metatileentities.MetaTileEntities;
import gregtech.integration.jei.multiblock.MultiblockInfoPage;
import gregtech.integration.jei.multiblock.MultiblockShapeInfo;
import gregtech.integration.jei.multiblock.channel.PlaceholderType;
import net.minecraft.client.resources.I18n;
import net.minecraft.util.EnumFacing;
import tj.blocks.BlockAbility;
import tj.blocks.TJMetaBlocks;
import tj.integration.jei.TJMultiblockShapeInfo;
import tj.machines.TJMetaTileEntities;
import tj.machines.multi.steam.MetaTileEntityLargeSolarBoiler;
import tj.util.Color;

public class LargeSolarBoilerInfo extends MultiblockInfoPage {

    private final boolean mega;

    public LargeSolarBoilerInfo(boolean mega) {
        this.mega = mega;
    }

    @Override
    public MetaTileEntityLargeSolarBoiler getController() {
        return this.mega ? TJMetaTileEntities.MEGA_SOLAR_BOILER : TJMetaTileEntities.LARGE_SOLAR_BOILER;
    }

    @Override
    public MultiblockShapeInfo getMatchingShapes(int extent) {
        final TJMultiblockShapeInfo.Builder builder = TJMultiblockShapeInfo.builder();
        if (!this.mega) {
            builder.aisle("FFF", "CCC", "CCC", "sss")
                    .aisle("IFM", "SPC", "OPC", "sss")
                    .aisle("FFm", "CCC", "CCC", "sss");
        } else {
         builder.aisle("FFFFFFFFFFFFFFF", "CCCCCCCCCCCCCCC", "CCCCCCCCCCCCCCC", "CCCCCCCCCCCCCCC", "CCCCCCCCCCCCCCC", "CCCCCCCCCCCCCCC", "CCCCCCCCCCCCCCC", "CCCCCCCCCCCCCCC", "CCCCCCCCCCCCCCC", "CCCCCCCCCCCCCCC", "CCCCCCCCCCCCCCC", "CCCCCCCCCCCCCCC", "CCCCCCCCCCCCCCC", "CCCCCCCCCCCCCCC", "CCCCCCCCCCCCCCC", "CCCCCCCCCCCCCCC", "CCCCCCCCCCCCCCC", "CCCCCCCCCCCCCCC", "CCCCCCCCCCCCCCC", "sssssssssssssss")
                 .aisle("FFFFFFFFFFFFFFF", "CPPPPPPPPPPPPPC", "CPPPPPPPPPPPPPC", "CPPPPPPPPPPPPPC", "CPPPPPPPPPPPPPC", "CPPPPPPPPPPPPPC", "CPPPPPPPPPPPPPC", "CPPPPPPPPPPPPPC", "CPPPPPPPPPPPPPC", "CPPPPPPPPPPPPPC", "CPPPPPPPPPPPPPC", "CPPPPPPPPPPPPPC", "CPPPPPPPPPPPPPC", "CPPPPPPPPPPPPPC", "CPPPPPPPPPPPPPC", "CPPPPPPPPPPPPPC", "CPPPPPPPPPPPPPC", "CPPPPPPPPPPPPPC", "CPPPPPPPPPPPPPC", "sssssssssssssss")
                 .aisle("FFFFFFFFFFFFFFF", "CPPPPPPPPPPPPPC", "CPPPPPPPPPPPPPC", "CPPPPPPPPPPPPPC", "CPPPPPPPPPPPPPC", "CPPPPPPPPPPPPPC", "CPPPPPPPPPPPPPC", "CPPPPPPPPPPPPPC", "CPPPPPPPPPPPPPC", "CPPPPPPPPPPPPPC", "CPPPPPPPPPPPPPC", "CPPPPPPPPPPPPPC", "CPPPPPPPPPPPPPC", "CPPPPPPPPPPPPPC", "CPPPPPPPPPPPPPC", "CPPPPPPPPPPPPPC", "CPPPPPPPPPPPPPC", "CPPPPPPPPPPPPPC", "CPPPPPPPPPPPPPC", "sssssssssssssss")
                 .aisle("FFFFFFFFFFFFFFF", "CPPPPPPPPPPPPPC", "CPPPPPPPPPPPPPC", "CPPPPPPPPPPPPPC", "CPPPPPPPPPPPPPC", "CPPPPPPPPPPPPPC", "CPPPPPPPPPPPPPC", "CPPPPPPPPPPPPPC", "CPPPPPPPPPPPPPC", "CPPPPPPPPPPPPPC", "CPPPPPPPPPPPPPC", "CPPPPPPPPPPPPPC", "CPPPPPPPPPPPPPC", "CPPPPPPPPPPPPPC", "CPPPPPPPPPPPPPC", "CPPPPPPPPPPPPPC", "CPPPPPPPPPPPPPC", "CPPPPPPPPPPPPPC", "CPPPPPPPPPPPPPC", "sssssssssssssss")
                 .aisle("FFFFFFFFFFFFFFF", "CPPPPPPPPPPPPPC", "CPPPPPPPPPPPPPC", "CPPPPPPPPPPPPPC", "CPPPPPPPPPPPPPC", "CPPPPPPPPPPPPPC", "CPPPPPPPPPPPPPC", "CPPPPPPPPPPPPPC", "CPPPPPPPPPPPPPC", "CPPPPPPPPPPPPPC", "CPPPPPPPPPPPPPC", "CPPPPPPPPPPPPPC", "CPPPPPPPPPPPPPC", "CPPPPPPPPPPPPPC", "CPPPPPPPPPPPPPC", "CPPPPPPPPPPPPPC", "CPPPPPPPPPPPPPC", "CPPPPPPPPPPPPPC", "CPPPPPPPPPPPPPC", "sssssssssssssss")
                 .aisle("FFFFFFFFFFFFFFF", "CPPPPPPPPPPPPPC", "CPPPPPPPPPPPPPC", "CPPPPPPPPPPPPPC", "CPPPPPPPPPPPPPC", "CPPPPPPPPPPPPPC", "CPPPPPPPPPPPPPC", "CPPPPPPPPPPPPPC", "CPPPPPPPPPPPPPC", "CPPPPPPPPPPPPPC", "CPPPPPPPPPPPPPC", "CPPPPPPPPPPPPPC", "CPPPPPPPPPPPPPC", "CPPPPPPPPPPPPPC", "CPPPPPPPPPPPPPC", "CPPPPPPPPPPPPPC", "CPPPPPPPPPPPPPC", "CPPPPPPPPPPPPPC", "CPPPPPPPPPPPPPC", "sssssssssssssss")
                 .aisle("FFFFFFFFFFFFFFF", "CPPPPPPPPPPPPPC", "CPPPPPPPPPPPPPC", "CPPPPPPPPPPPPPC", "CPPPPPPPPPPPPPC", "CPPPPPPPPPPPPPC", "CPPPPPPPPPPPPPC", "CPPPPPPPPPPPPPC", "CPPPPPPPPPPPPPC", "CPPPPPPPPPPPPPC", "CPPPPPPPPPPPPPC", "CPPPPPPPPPPPPPC", "CPPPPPPPPPPPPPC", "CPPPPPPPPPPPPPC", "CPPPPPPPPPPPPPC", "CPPPPPPPPPPPPPC", "CPPPPPPPPPPPPPC", "CPPPPPPPPPPPPPC", "CPPPPPPPPPPPPPC", "sssssssssssssss")
                 .aisle("IFFFFFFFFFFFFFM", "OPPPPPPPPPPPPPC", "SPPPPPPPPPPPPPC", "CPPPPPPPPPPPPPC", "CPPPPPPPPPPPPPC", "CPPPPPPPPPPPPPC", "CPPPPPPPPPPPPPC", "CPPPPPPPPPPPPPC", "CPPPPPPPPPPPPPC", "CPPPPPPPPPPPPPC", "CPPPPPPPPPPPPPC", "CPPPPPPPPPPPPPC", "CPPPPPPPPPPPPPC", "CPPPPPPPPPPPPPC", "CPPPPPPPPPPPPPC", "CPPPPPPPPPPPPPC", "CPPPPPPPPPPPPPC", "CPPPPPPPPPPPPPC", "CPPPPPPPPPPPPPC", "sssssssssssssss")
                 .aisle("FFFFFFFFFFFFFFm", "CPPPPPPPPPPPPPC", "CPPPPPPPPPPPPPC", "CPPPPPPPPPPPPPC", "CPPPPPPPPPPPPPC", "CPPPPPPPPPPPPPC", "CPPPPPPPPPPPPPC", "CPPPPPPPPPPPPPC", "CPPPPPPPPPPPPPC", "CPPPPPPPPPPPPPC", "CPPPPPPPPPPPPPC", "CPPPPPPPPPPPPPC", "CPPPPPPPPPPPPPC", "CPPPPPPPPPPPPPC", "CPPPPPPPPPPPPPC", "CPPPPPPPPPPPPPC", "CPPPPPPPPPPPPPC", "CPPPPPPPPPPPPPC", "CPPPPPPPPPPPPPC", "sssssssssssssss")
                 .aisle("FFFFFFFFFFFFFFF", "CPPPPPPPPPPPPPC", "CPPPPPPPPPPPPPC", "CPPPPPPPPPPPPPC", "CPPPPPPPPPPPPPC", "CPPPPPPPPPPPPPC", "CPPPPPPPPPPPPPC", "CPPPPPPPPPPPPPC", "CPPPPPPPPPPPPPC", "CPPPPPPPPPPPPPC", "CPPPPPPPPPPPPPC", "CPPPPPPPPPPPPPC", "CPPPPPPPPPPPPPC", "CPPPPPPPPPPPPPC", "CPPPPPPPPPPPPPC", "CPPPPPPPPPPPPPC", "CPPPPPPPPPPPPPC", "CPPPPPPPPPPPPPC", "CPPPPPPPPPPPPPC", "sssssssssssssss")
                 .aisle("FFFFFFFFFFFFFFF", "CPPPPPPPPPPPPPC", "CPPPPPPPPPPPPPC", "CPPPPPPPPPPPPPC", "CPPPPPPPPPPPPPC", "CPPPPPPPPPPPPPC", "CPPPPPPPPPPPPPC", "CPPPPPPPPPPPPPC", "CPPPPPPPPPPPPPC", "CPPPPPPPPPPPPPC", "CPPPPPPPPPPPPPC", "CPPPPPPPPPPPPPC", "CPPPPPPPPPPPPPC", "CPPPPPPPPPPPPPC", "CPPPPPPPPPPPPPC", "CPPPPPPPPPPPPPC", "CPPPPPPPPPPPPPC", "CPPPPPPPPPPPPPC", "CPPPPPPPPPPPPPC", "sssssssssssssss")
                 .aisle("FFFFFFFFFFFFFFF", "CPPPPPPPPPPPPPC", "CPPPPPPPPPPPPPC", "CPPPPPPPPPPPPPC", "CPPPPPPPPPPPPPC", "CPPPPPPPPPPPPPC", "CPPPPPPPPPPPPPC", "CPPPPPPPPPPPPPC", "CPPPPPPPPPPPPPC", "CPPPPPPPPPPPPPC", "CPPPPPPPPPPPPPC", "CPPPPPPPPPPPPPC", "CPPPPPPPPPPPPPC", "CPPPPPPPPPPPPPC", "CPPPPPPPPPPPPPC", "CPPPPPPPPPPPPPC", "CPPPPPPPPPPPPPC", "CPPPPPPPPPPPPPC", "CPPPPPPPPPPPPPC", "sssssssssssssss")
                 .aisle("FFFFFFFFFFFFFFF", "CPPPPPPPPPPPPPC", "CPPPPPPPPPPPPPC", "CPPPPPPPPPPPPPC", "CPPPPPPPPPPPPPC", "CPPPPPPPPPPPPPC", "CPPPPPPPPPPPPPC", "CPPPPPPPPPPPPPC", "CPPPPPPPPPPPPPC", "CPPPPPPPPPPPPPC", "CPPPPPPPPPPPPPC", "CPPPPPPPPPPPPPC", "CPPPPPPPPPPPPPC", "CPPPPPPPPPPPPPC", "CPPPPPPPPPPPPPC", "CPPPPPPPPPPPPPC", "CPPPPPPPPPPPPPC", "CPPPPPPPPPPPPPC", "CPPPPPPPPPPPPPC", "sssssssssssssss")
                 .aisle("FFFFFFFFFFFFFFF", "CPPPPPPPPPPPPPC", "CPPPPPPPPPPPPPC", "CPPPPPPPPPPPPPC", "CPPPPPPPPPPPPPC", "CPPPPPPPPPPPPPC", "CPPPPPPPPPPPPPC", "CPPPPPPPPPPPPPC", "CPPPPPPPPPPPPPC", "CPPPPPPPPPPPPPC", "CPPPPPPPPPPPPPC", "CPPPPPPPPPPPPPC", "CPPPPPPPPPPPPPC", "CPPPPPPPPPPPPPC", "CPPPPPPPPPPPPPC", "CPPPPPPPPPPPPPC", "CPPPPPPPPPPPPPC", "CPPPPPPPPPPPPPC", "CPPPPPPPPPPPPPC", "sssssssssssssss")
                 .aisle("FFFFFFFFFFFFFFF", "CCCCCCCCCCCCCCC", "CCCCCCCCCCCCCCC", "CCCCCCCCCCCCCCC", "CCCCCCCCCCCCCCC", "CCCCCCCCCCCCCCC", "CCCCCCCCCCCCCCC", "CCCCCCCCCCCCCCC", "CCCCCCCCCCCCCCC", "CCCCCCCCCCCCCCC", "CCCCCCCCCCCCCCC", "CCCCCCCCCCCCCCC", "CCCCCCCCCCCCCCC", "CCCCCCCCCCCCCCC", "CCCCCCCCCCCCCCC", "CCCCCCCCCCCCCCC", "CCCCCCCCCCCCCCC", "CCCCCCCCCCCCCCC", "CCCCCCCCCCCCCCC", "sssssssssssssss");
        }
        return builder.where('S', this.getController(), EnumFacing.WEST)
                .where('M', GATileEntities.MAINTENANCE_HATCH[0], EnumFacing.EAST)
                .where('m', PlaceholderType.MUFFLER, GATileEntities.MUFFLER_HATCH[0], EnumFacing.EAST)
                .where('F', MetaBlocks.BOILER_FIREBOX_CASING.getState(BlockFireboxCasing.FireboxCasingType.STEEL_FIREBOX))
                .where('C', MetaBlocks.METAL_CASING.getState(BlockMetalCasing.MetalCasingType.STEEL_SOLID))
                .where('P', MetaBlocks.BOILER_CASING.getState(BlockBoilerCasing.BoilerCasingType.STEEL_PIPE))
                .where('s', TJMetaBlocks.ABILITY_BLOCKS.getState(BlockAbility.AbilityType.SOLAR_COLLECTOR))
                .where('I', PlaceholderType.INPUT_HATCH,MetaTileEntities.FLUID_IMPORT_HATCH[0], EnumFacing.WEST)
                .where('O',PlaceholderType.OUTPUT_HATCH, MetaTileEntities.FLUID_EXPORT_HATCH[0], EnumFacing.WEST)
                .build();

    }

    @Override
    public String[] getDescription() {
        return new String[]{I18n.format("tj.multiblock.large_solar_boiler.description"),
                this.mega ? I18n.format("tj.multiblock.mega_boiler.parallel.description", this.getController().getMaxParallel()).replace("§7", "§r") : "",
                this.mega ? (Color.YELLOW + I18n.format("tj.multiblock.mega_boiler.warning")) : ""};
    }

    @Override
    public float getDefaultZoom() {
        return this.mega ? 0.3F : super.getDefaultZoom();
    }
}
